<?xml version="1.0"?>
<robot xmlns:xacro="http://www.ros.org/wiki/xacro">

<!-- 
    _____________________________________________________________________
        include this file into: /description/hyperdog.urdf.xacro 
        using following line: 
                    <xacro:include filename="hyperdog_urdf_joints.xacro" /> 
    _____________________________________________________________________ -->

    <xacro:include filename="consts.xacro" /> 

    <!-- Limits -->
    <xacro:macro name="hip_limits">
        <limit lower="${hip_low_limit}" upper="${hip_up_limit}" velocity="${velocity}" effort="${effort}"/> <!-- effort = 7 -->
    </xacro:macro>
    <xacro:macro name="uleg_limits">
        <limit lower="${uleg_low_limit}" upper="${uleg_up_limit}" velocity="${velocity}" effort="${effort}"/>
    </xacro:macro>
    <xacro:macro name="lleg_limits">
        <limit lower="${lleg_low_limit}" upper="${lleg_up_limit}" velocity="${velocity}" effort="${effort}"/>
    </xacro:macro>


    <!-- ******** Inertial-base joint ********** -->
    <joint name="inertial_joint" type="fixed">
        <parent link="base_link"/>
        <child link="inertial_link"/>
    </joint>

    <!-- *********  FR_hip joint ********* -->
    <joint name="FR_hip_joint" type="revolute">
        <axis xyz="-1 0 0"/>
        <origin xyz="0.175 -0.066 0" rpy="0 0 0"/>
        <parent link="base_link"/>
        <child link="FR_hip_link"/>
        <xacro:hip_limits></xacro:hip_limits>
        <xacro:if value="${use_dynamics}">
            <xacro:hip_joint_dynamics></xacro:hip_joint_dynamics>
        </xacro:if>
    </joint>
    <!-- *********  FL_hip  ********* -->
    <joint name="FL_hip_joint" type="revolute">
        <axis xyz="1 0 0"/>
        <origin xyz="0.175 0.066 0" rpy="0 0 0"/>
        <parent link="base_link"/>
        <child link="FL_hip_link"/>
        <xacro:hip_limits></xacro:hip_limits>
        <xacro:if value="${use_dynamics}">
            <xacro:hip_joint_dynamics></xacro:hip_joint_dynamics>
        </xacro:if>
    </joint>
    <!-- *********  BR_hip  ********* -->
    <joint name="BR_hip_joint" type="revolute">
        <axis xyz="-1 0 0"/>
        <origin xyz="-0.175 -0.066 0" rpy="0 0 0"/>
        <parent link="base_link"/>
        <child link="BR_hip_link"/>
        <xacro:hip_limits></xacro:hip_limits>
        <xacro:if value="${use_dynamics}">
            <xacro:hip_joint_dynamics></xacro:hip_joint_dynamics>
        </xacro:if>
    </joint>
    <!-- *********  BL_hip  ********* -->
    <joint name="BL_hip_joint" type="revolute">
        <axis xyz="1 0 0"/>
        <origin xyz="-0.175 0.066 0" rpy="0 0 0"/>
        <parent link="base_link"/>
        <child link="BL_hip_link"/>
        <xacro:hip_limits></xacro:hip_limits>
        <xacro:if value="${use_dynamics}">
            <xacro:hip_joint_dynamics></xacro:hip_joint_dynamics>
        </xacro:if>
    </joint>
    



    <!-- *********  FR_uleg joint ********* -->
    <joint name="FR_uleg_joint" type="revolute">
        <axis xyz="0 -1 0"/>
        <origin xyz="0 -0.104 0" rpy="0 0 0"/>
        <parent link="FR_hip_link"/>
        <child link="FR_uleg_link"/>
        <xacro:uleg_limits></xacro:uleg_limits>
        <xacro:if value="${use_dynamics}">
            <xacro:uleg_joint_dynamics></xacro:uleg_joint_dynamics>
        </xacro:if>
    </joint>
    <!-- *********  FL_uleg  ********* -->
    <joint name="FL_uleg_joint" type="revolute">
        <axis xyz="0 -1 0"/>
        <origin xyz="0 0.104 0" rpy="0 0 0"/>
        <parent link="FL_hip_link"/>
        <child link="FL_uleg_link"/>
        <xacro:uleg_limits></xacro:uleg_limits>
        <xacro:if value="${use_dynamics}">
            <xacro:uleg_joint_dynamics></xacro:uleg_joint_dynamics>
        </xacro:if>
    </joint>
    <!-- *********  BR_uleg  ********* -->
    <joint name="BR_uleg_joint" type="revolute">
        <axis xyz="0 -1 0"/>
        <origin xyz="0 -0.104 0" rpy="0 0 0"/>
        <parent link="BR_hip_link"/>
        <child link="BR_uleg_link"/>
        <xacro:uleg_limits></xacro:uleg_limits>
        <xacro:if value="${use_dynamics}">
            <xacro:uleg_joint_dynamics></xacro:uleg_joint_dynamics>
        </xacro:if>
    </joint>
    <!-- *********  BL_uleg  ********* -->
    <joint name="BL_uleg_joint" type="revolute">
        <axis xyz="0 -1 0"/>
        <origin xyz="0 0.104 0" rpy="0 0 0"/>
        <parent link="BL_hip_link"/>
        <child link="BL_uleg_link"/>
        <xacro:uleg_limits></xacro:uleg_limits>
        <xacro:if value="${use_dynamics}">
            <xacro:uleg_joint_dynamics></xacro:uleg_joint_dynamics>
        </xacro:if>
    </joint>



    <!-- *********  FR_lleg  ********* -->
    <joint name="FR_lleg_joint" type="revolute">
        <axis xyz="0 1 0"/>
        <origin xyz="-0.15 0 0" rpy="0 0.0 0"/>
        <parent link="FR_uleg_link"/>
        <child link="FR_lleg_link"/>
        <xacro:lleg_limits></xacro:lleg_limits>
        <xacro:if value="${use_dynamics}">
            <xacro:lleg_joint_dynamics></xacro:lleg_joint_dynamics>
        </xacro:if>
    </joint>
    <!-- *********  FL_lleg  ********* -->
    <joint name="FL_lleg_joint" type="revolute">
        <axis xyz="0 1 0"/>
        <origin xyz="-0.15 0 0" rpy="0 0.0 0"/>
        <parent link="FL_uleg_link"/>
        <child link="FL_lleg_link"/>
        <xacro:lleg_limits></xacro:lleg_limits>
        <xacro:if value="${use_dynamics}">
            <xacro:lleg_joint_dynamics></xacro:lleg_joint_dynamics>
        </xacro:if>
    </joint>
    <!-- *********  BR_lleg  ********* -->
    <joint name="BR_lleg_joint" type="revolute">
        <origin xyz="-0.15 0 0" rpy="0 0.0 0"/>
        <parent link="BR_uleg_link"/>
        <child link="BR_lleg_link"/>
        <axis xyz="0 1 0"/>
        <xacro:lleg_limits></xacro:lleg_limits>
        <xacro:if value="${use_dynamics}">
            <xacro:lleg_joint_dynamics></xacro:lleg_joint_dynamics>
        </xacro:if>
    </joint>
    <!-- *********  BL_lleg  ********* -->
    <joint name="BL_lleg_joint" type="revolute">
        <axis xyz="0 1 0"/>
        <origin xyz="-0.15 0 0" rpy="0 0.0 0"/>
        <parent link="BL_uleg_link"/>
        <child link="BL_lleg_link"/>
        <xacro:lleg_limits></xacro:lleg_limits>
        <xacro:if value="${use_dynamics}">
            <xacro:lleg_joint_dynamics></xacro:lleg_joint_dynamics>
        </xacro:if>
    </joint>



     <!-- *********  FR_FOOT  ********* -->
     <joint name="FR_foot_fixed" type="fixed">
        <origin rpy="0 0 0" xyz="0.14 0 0"/>
        <parent link="FR_lleg_link"/>
        <child link="FR_foot"/>
      </joint>
     <!-- *********  FL_FOOT  ********* -->
     <joint name="FL_foot_fixed" type="fixed">
        <origin rpy="0 0 0" xyz="0.14 0 0"/>
        <parent link="FL_lleg_link"/>
        <child link="FL_foot"/>
      </joint>
     <!-- *********  BR_FOOT  ********* -->
     <joint name="BR_foot_fixed" type="fixed">
        <origin rpy="0 0 0" xyz="0.14 0 0"/>
        <parent link="BR_lleg_link"/>
        <child link="BR_foot"/>
      </joint>
    <!-- *********  BL_FOOT  ********* -->
    <joint name="BL_foot_fixed" type="fixed">
        <origin rpy="0 0 0" xyz="0.14 0 0"/>
        <parent link="BL_lleg_link"/>
        <child link="BL_foot"/>
      </joint>
</robot>