<?xml version="1.0"?>
<robot xmlns:xacro="http://www.ros.org/wiki/xacro">

<!-- 
    _____________________________________________________________________
        include this file into: /description/hyperdog.urdf.xacro 
        using following line: 
                    <xacro:include filename="hyperdog_urdf_joints.xacro" /> 
    _____________________________________________________________________ -->

    <!-- *********  FR_hip  ********* -->
    <joint name="FR_hip_joint" type="revolute">
        <axis xyz="-1 0 0"/>
        <origin xyz="0.175 -0.066 0" rpy="0 0 0"/>
        <parent link="rob_link"/>
        <child link="FR_hip_link"/>
        <limit lower="-1.57" upper="1.57" velocity="1" effort="7"/> 
        <dynamics friction="10.0"/>
    </joint>

    <!-- *********  FR_uleg  ********* -->
    <joint name="FR_uleg_joint" type="revolute">
        <axis xyz="0 -1 0"/>
        <origin xyz="0 -0.104 0" rpy="0 0 0"/>
        <parent link="FR_hip_link"/>
        <child link="FR_uleg_link"/>
        <limit lower="-1.2217" upper="3.14" velocity="1" effort="7"/>
        <dynamics friction="10.0"/> 
    </joint>

    <!-- *********  FR_lleg  ********* -->
    <joint name="FR_lleg_joint" type="revolute">
        <axis xyz="0 1 0"/>
        <origin xyz="-0.15 0 0" rpy="0 0.0 0"/>
        <parent link="FR_uleg_link"/>
        <child link="FR_lleg_link"/>
        <limit lower="-1.57" upper="2.618" velocity="1" effort="7"/>
        <xacro:lleg_jointDynamics></xacro:lleg_jointDynamics> 
    </joint>


    <!-- *********  FL_hip  ********* -->
    <joint name="FL_hip_joint" type="revolute">
        <axis xyz="1 0 0"/>
        <origin xyz="0.175 0.066 0" rpy="0 0 0"/>
        <parent link="rob_link"/>
        <child link="FL_hip_link"/>
        <limit lower="-1.57" upper="1.57" velocity="1" effort="7"/> 
        <dynamics friction="10.0"/>
    </joint>


    <!-- *********  FL_uleg  ********* -->
    <joint name="FL_uleg_joint" type="revolute">
        <axis xyz="0 -1 0"/>
        <origin xyz="0 0.104 0" rpy="0 0 0"/>
        <parent link="FL_hip_link"/>
        <child link="FL_uleg_link"/>
        <limit lower="-1.2217" upper="3.14" velocity="1" effort="7"/> 
        <dynamics friction="10.0"/>
    </joint>


    <!-- *********  FL_lleg  ********* -->
    <joint name="FL_lleg_joint" type="revolute">
        <axis xyz="0 1 0"/>
        <origin xyz="-0.15 0 0" rpy="0 0.0 0"/>
        <parent link="FL_uleg_link"/>
        <child link="FL_lleg_link"/>
        <limit lower="-1.57" upper="2.618" velocity="1" effort="7"/> 
        <xacro:lleg_jointDynamics></xacro:lleg_jointDynamics> 
    </joint>

    <!-- *********  BR_hip  ********* -->
    <joint name="BR_hip_joint" type="revolute">
        <axis xyz="-1 0 0"/>
        <origin xyz="-0.175 -0.066 0" rpy="0 0 0"/>
        <parent link="rob_link"/>
        <child link="BR_hip_link"/>
        <limit lower="-1.57" upper="1.57" velocity="1" effort="7"/> 
        <dynamics friction="10.0"/>
    </joint>



    <!-- *********  BR_uleg  ********* -->
    <joint name="BR_uleg_joint" type="revolute">
        <axis xyz="0 -1 0"/>
        <origin xyz="0 -0.104 0" rpy="0 0 0"/>
        <parent link="BR_hip_link"/>
        <child link="BR_uleg_link"/>
        <limit lower="-1.2217" upper="3.14" velocity="1" effort="7"/> 
        <dynamics friction="10.0"/>
    </joint>

    <!-- *********  BR_lleg  ********* -->
    <joint name="BR_lleg_joint" type="revolute">
        <origin xyz="-0.15 0 0" rpy="0 0.0 0"/>
        <parent link="BR_uleg_link"/>
        <child link="BR_lleg_link"/>
        <axis xyz="0 1 0"/>
        <limit lower="-1.57" upper="2.618" velocity="1" effort="7"/> 
        <xacro:lleg_jointDynamics></xacro:lleg_jointDynamics> 
    </joint>


    <!-- *********  BL_hip  ********* -->
    <joint name="BL_hip_joint" type="revolute">
        <axis xyz="1 0 0"/>
        <origin xyz="-0.175 0.066 0" rpy="0 0 0"/>
        <parent link="rob_link"/>
        <child link="BL_hip_link"/>
        <limit lower="-1.57" upper="1.57" velocity="1" effort="7"/> 
        <dynamics friction="10.0"/>
    </joint>

    <!-- *********  BL_uleg  ********* -->
    <joint name="BL_uleg_joint" type="revolute">
        <axis xyz="0 -1 0"/>
        <origin xyz="0 0.104 0" rpy="0 0 0"/>
        <parent link="BL_hip_link"/>
        <child link="BL_uleg_link"/>
        <limit lower="-1.2217" upper="3.14" velocity="1" effort="7"/> 
        <dynamics friction="10.0"/>
    </joint>

    <!-- *********  BL_lleg  ********* -->
    <joint name="BL_lleg_joint" type="revolute">
        <axis xyz="0 1 0"/>
        <origin xyz="-0.15 0 0" rpy="0 0.0 0"/>
        <parent link="BL_uleg_link"/>
        <child link="BL_lleg_link"/>
        <limit lower="-1.57" upper="2.618" velocity="1" effort="7"/> 
        <xacro:lleg_jointDynamics></xacro:lleg_jointDynamics> 
    </joint>

</robot>